/home/pi/rpi_temp/tempsens/tasks.py:11: RuntimeWarning: This channel is already in use, continuing anyway.  Use GPIO.setwarnings(False) to disable warnings.
  GPIO.setup(led, GPIO.OUT)
[2020-11-17 18:05:54,848: INFO/MainProcess] Connected to redis://localhost:6379//
[2020-11-17 18:05:55,554: INFO/MainProcess] mingle: searching for neighbors
[2020-11-17 18:05:57,847: INFO/MainProcess] mingle: all alone
[2020-11-17 18:05:58,672: WARNING/MainProcess] /usr/local/lib/python3.7/dist-packages/celery/fixups/django.py:203: UserWarning: Using settings.DEBUG leads to a memory
            leak, never use this setting in production environments!
  leak, never use this setting in production environments!''')
[2020-11-17 18:05:58,684: INFO/MainProcess] celery@worker1 ready.
[2020-11-17 18:06:20,650: INFO/MainProcess] Received task: tempsens.tasks.getInfo[9f930b56-2594-48ce-b4c0-c0bd24e00b31]  
/home/pi/rpi_temp/tempsens/tasks.py:11: RuntimeWarning: This channel is already in use, continuing anyway.  Use GPIO.setwarnings(False) to disable warnings.
  GPIO.setup(led, GPIO.OUT)
[2020-11-17 18:06:21,375: INFO/ForkPoolWorker-1] Task tempsens.tasks.getInfo[9f930b56-2594-48ce-b4c0-c0bd24e00b31] succeeded in 0.6780647399999964s: {'temp': 23.0, 'hum': 62.0}
[2020-11-17 18:06:24,787: INFO/MainProcess] Received task: tempsens.tasks.powerOnLed[7021cb38-f745-4f38-aa54-5dd25c7263f2]  
[2020-11-17 18:06:24,893: INFO/ForkPoolWorker-1] Task tempsens.tasks.powerOnLed[7021cb38-f745-4f38-aa54-5dd25c7263f2] succeeded in 0.03312877500002287s: None
[2020-11-17 18:06:27,811: INFO/MainProcess] Received task: tempsens.tasks.powerOnLed[dbde33a3-1cae-4fa5-bc9a-970313ece3f4]  
[2020-11-17 18:06:27,869: INFO/ForkPoolWorker-1] Task tempsens.tasks.powerOnLed[dbde33a3-1cae-4fa5-bc9a-970313ece3f4] succeeded in 0.031205698000007942s: None
[2020-11-17 18:06:32,829: INFO/MainProcess] Received task: tempsens.tasks.getInfo[88011dcd-5a3f-4826-a3f9-e2c8ad7efcb5]  
[2020-11-17 18:06:33,407: INFO/ForkPoolWorker-1] Task tempsens.tasks.getInfo[88011dcd-5a3f-4826-a3f9-e2c8ad7efcb5] succeeded in 0.5597685710000064s: {'temp': 23.0, 'hum': 61.0}
[2020-11-17 18:07:07,245: INFO/MainProcess] Received task: tempsens.tasks.powerOnLed[724f472e-e474-4d18-b02b-9a8803d48f26]  
[2020-11-17 18:07:07,296: INFO/ForkPoolWorker-1] Task tempsens.tasks.powerOnLed[724f472e-e474-4d18-b02b-9a8803d48f26] succeeded in 0.037457563000032223s: None
[2020-11-17 18:07:15,330: INFO/MainProcess] Received task: tempsens.tasks.powerOffLed[09bbac65-f8f6-4b2d-8379-b718c2f28b9b]  
[2020-11-17 18:07:15,386: INFO/ForkPoolWorker-1] Task tempsens.tasks.powerOffLed[09bbac65-f8f6-4b2d-8379-b718c2f28b9b] succeeded in 0.020320292000008067s: None
[2020-11-20 14:59:13,487: INFO/MainProcess] Received task: tempsens.tasks.getInfo[9c03cd8f-9612-47fb-a455-ac6cc555247e]  
[2020-11-20 14:59:16,616: INFO/ForkPoolWorker-1] Task tempsens.tasks.getInfo[9c03cd8f-9612-47fb-a455-ac6cc555247e] succeeded in 3.0855753740179352s: {'temp': 23.0, 'hum': 63.0}
[2020-11-23 19:48:22,245: INFO/MainProcess] Received task: tempsens.tasks.getInfo[f1e07324-9132-43e9-a4f6-960fa40f0486]  
[2020-11-23 19:48:22,823: INFO/ForkPoolWorker-1] Task tempsens.tasks.getInfo[f1e07324-9132-43e9-a4f6-960fa40f0486] succeeded in 0.564363650046289s: {'temp': 23.0, 'hum': 60.0}
[2020-11-23 19:48:28,503: INFO/MainProcess] Received task: tempsens.tasks.getInfo[70961ace-8b33-4bf4-bd5f-f53fafa4efd4]  
[2020-11-23 19:48:36,456: INFO/MainProcess] Received task: tempsens.tasks.getInfo[23fd8278-ba22-46b3-8ff2-8d50e270b1da]  
[2020-11-23 19:49:06,549: ERROR/ForkPoolWorker-1] Task tempsens.tasks.getInfo[70961ace-8b33-4bf4-bd5f-f53fafa4efd4] raised unexpected: TypeError("'<' not supported between instances of 'NoneType' and 'int'")
Traceback (most recent call last):
  File "/usr/local/lib/python3.7/dist-packages/celery/app/trace.py", line 385, in trace_task
    R = retval = fun(*args, **kwargs)
  File "/usr/local/lib/python3.7/dist-packages/celery/app/trace.py", line 650, in __protected_call__
    return self.run(*args, **kwargs)
  File "/home/pi/rpi_temp/tempsens/tasks.py", line 40, in getInfo
    checkTemperature(temperature, humidity, led)
  File "/usr/local/lib/python3.7/dist-packages/celery/local.py", line 191, in __call__
    return self._get_current_object()(*a, **kw)
  File "/usr/local/lib/python3.7/dist-packages/celery/app/trace.py", line 651, in __protected_call__
    return orig(self, *args, **kwargs)
  File "/usr/local/lib/python3.7/dist-packages/celery/app/task.py", line 392, in __call__
    return self.run(*args, **kwargs)
  File "/home/pi/rpi_temp/tempsens/tasks.py", line 21, in checkTemperature
    if(temperature < 21):
TypeError: '<' not supported between instances of 'NoneType' and 'int'
[2020-11-23 19:49:44,531: ERROR/ForkPoolWorker-1] Task tempsens.tasks.getInfo[23fd8278-ba22-46b3-8ff2-8d50e270b1da] raised unexpected: TypeError("'<' not supported between instances of 'NoneType' and 'int'")
Traceback (most recent call last):
  File "/usr/local/lib/python3.7/dist-packages/celery/app/trace.py", line 385, in trace_task
    R = retval = fun(*args, **kwargs)
  File "/usr/local/lib/python3.7/dist-packages/celery/app/trace.py", line 650, in __protected_call__
    return self.run(*args, **kwargs)
  File "/home/pi/rpi_temp/tempsens/tasks.py", line 40, in getInfo
    checkTemperature(temperature, humidity, led)
  File "/usr/local/lib/python3.7/dist-packages/celery/local.py", line 191, in __call__
    return self._get_current_object()(*a, **kw)
  File "/usr/local/lib/python3.7/dist-packages/celery/app/trace.py", line 651, in __protected_call__
    return orig(self, *args, **kwargs)
  File "/usr/local/lib/python3.7/dist-packages/celery/app/task.py", line 392, in __call__
    return self.run(*args, **kwargs)
  File "/home/pi/rpi_temp/tempsens/tasks.py", line 21, in checkTemperature
    if(temperature < 21):
TypeError: '<' not supported between instances of 'NoneType' and 'int'
[2020-11-23 19:51:30,226: INFO/MainProcess] Received task: tempsens.tasks.getInfo[32746a56-6a22-4628-ad48-9705cdc72da9]  
[2020-11-23 19:51:51,043: INFO/ForkPoolWorker-1] Task tempsens.tasks.getInfo[32746a56-6a22-4628-ad48-9705cdc72da9] succeeded in 20.80003043706529s: {'temp': 24.0, 'hum': 43.0}
[2020-11-23 19:52:13,312: INFO/MainProcess] Received task: tempsens.tasks.getInfo[16e1cd36-3cb5-4400-9575-657e2a250358]  
[2020-11-23 19:52:16,398: INFO/ForkPoolWorker-1] Task tempsens.tasks.getInfo[16e1cd36-3cb5-4400-9575-657e2a250358] succeeded in 3.076487921993248s: {'temp': 23.0, 'hum': 45.0}
[2020-11-23 19:52:27,594: INFO/MainProcess] Received task: tempsens.tasks.powerOnLed[d8b9aeeb-ddbf-4ea8-8337-0de35f8e1c00]  
[2020-11-23 19:52:27,642: INFO/ForkPoolWorker-1] Task tempsens.tasks.powerOnLed[d8b9aeeb-ddbf-4ea8-8337-0de35f8e1c00] succeeded in 0.030202801921404898s: None
[2020-11-23 19:52:27,966: INFO/MainProcess] Received task: tempsens.tasks.getInfo[79a8bb56-bb41-4158-95cd-1546fc0e3bf8]  
[2020-11-23 19:52:31,074: INFO/ForkPoolWorker-1] Task tempsens.tasks.getInfo[79a8bb56-bb41-4158-95cd-1546fc0e3bf8] succeeded in 3.0820288159884512s: {'temp': 23.0, 'hum': 45.0}
[2020-11-25 16:53:23,369: INFO/MainProcess] Received task: tempsens.tasks.getInfo[f3021b45-e526-4273-976b-4865b077496c]  
[2020-11-25 16:53:41,837: INFO/ForkPoolWorker-1] Task tempsens.tasks.getInfo[f3021b45-e526-4273-976b-4865b077496c] succeeded in 18.424000464961864s: {'temp': 25.0, 'hum': 55.0}
Error: 
Unable to load celery application.
The module temp_website was not found.

