/home/pi/rpi_temp/django_app/tempsens/tasks.py:11: RuntimeWarning: This channel is already in use, continuing anyway.  Use GPIO.setwarnings(False) to disable warnings.
  GPIO.setup(led, GPIO.OUT)
[2020-11-25 17:03:01,673: INFO/MainProcess] Connected to redis://localhost:6379//
[2020-11-25 17:03:03,115: INFO/MainProcess] mingle: searching for neighbors
[2020-11-25 17:03:08,410: INFO/MainProcess] mingle: all alone
[2020-11-25 17:03:10,465: WARNING/MainProcess] /usr/local/lib/python3.7/dist-packages/celery/fixups/django.py:203: UserWarning: Using settings.DEBUG leads to a memory
            leak, never use this setting in production environments!
  leak, never use this setting in production environments!''')
[2020-11-25 17:03:10,467: INFO/MainProcess] celery@worker2 ready.
[2020-11-25 17:06:21,022: INFO/MainProcess] Received task: tempsens.tasks.getInfo[43b4474d-1481-4fea-8a28-6ebf02950513]  
/home/pi/rpi_temp/django_app/tempsens/tasks.py:11: RuntimeWarning: This channel is already in use, continuing anyway.  Use GPIO.setwarnings(False) to disable warnings.
  GPIO.setup(led, GPIO.OUT)
[2020-11-25 17:06:21,863: INFO/ForkPoolWorker-1] Task tempsens.tasks.getInfo[43b4474d-1481-4fea-8a28-6ebf02950513] succeeded in 0.6787151620000031s: {'temp': 25.0, 'hum': 55.0}
[2020-11-25 17:13:40,457: INFO/MainProcess] Received task: tempsens.tasks.getInfo[b24c1ffb-6b26-429e-bd46-b644f563bc5b]  
[2020-11-25 17:13:43,564: INFO/ForkPoolWorker-1] Task tempsens.tasks.getInfo[b24c1ffb-6b26-429e-bd46-b644f563bc5b] succeeded in 3.09583641800009s: {'temp': 24.0, 'hum': 56.0}
[2020-11-25 17:23:48,944: INFO/MainProcess] Received task: tempsens.tasks.getInfo[b40041f9-8fb5-4388-9f67-a9b1bfdaa77d]  
[2020-11-25 17:23:52,060: INFO/ForkPoolWorker-1] Task tempsens.tasks.getInfo[b40041f9-8fb5-4388-9f67-a9b1bfdaa77d] succeeded in 3.1002314659999683s: {'temp': 24.0, 'hum': 55.0}
[2020-11-25 17:43:39,800: INFO/MainProcess] Received task: tempsens.tasks.getInfo[75e8e84a-2120-4327-9857-75b02f909f47]  
[2020-11-25 17:43:40,387: INFO/ForkPoolWorker-1] Task tempsens.tasks.getInfo[75e8e84a-2120-4327-9857-75b02f909f47] succeeded in 0.553680907999933s: {'temp': 24.0, 'hum': 55.0}
[2020-11-25 17:52:08,313: INFO/MainProcess] Received task: tempsens.tasks.powerOffLed[ff931e68-37ab-4569-9619-8d909b3d7c52]  
[2020-11-25 17:52:08,361: INFO/ForkPoolWorker-1] Task tempsens.tasks.powerOffLed[ff931e68-37ab-4569-9619-8d909b3d7c52] succeeded in 0.01896389800003817s: None
[2020-11-25 18:09:38,341: INFO/MainProcess] Received task: tempsens.tasks.getInfo[806e335c-afa4-4b8c-b02b-fe81bff54b65]  
[2020-11-25 18:09:41,431: INFO/ForkPoolWorker-1] Task tempsens.tasks.getInfo[806e335c-afa4-4b8c-b02b-fe81bff54b65] succeeded in 3.071287267000116s: {'temp': 24.0, 'hum': 53.0}
[2020-11-26 18:13:28,252: INFO/MainProcess] Received task: tempsens.tasks.getInfo[9473b8d9-3d7c-47d4-99e9-58f35946c01a]  
[2020-11-26 18:13:28,845: INFO/ForkPoolWorker-1] Task tempsens.tasks.getInfo[9473b8d9-3d7c-47d4-99e9-58f35946c01a] succeeded in 0.5694526010047412s: {'temp': 24.0, 'hum': 54.0}
[2020-11-26 18:17:32,591: INFO/MainProcess] Received task: tempsens.tasks.getInfo[535bddfd-e9da-43fe-8a13-9c7df6bf38f3]  
[2020-11-26 18:17:33,191: INFO/ForkPoolWorker-1] Task tempsens.tasks.getInfo[535bddfd-e9da-43fe-8a13-9c7df6bf38f3] succeeded in 0.5613071949919686s: {'temp': 24.0, 'hum': 53.0}
[2020-11-26 18:26:13,317: INFO/MainProcess] Received task: tempsens.tasks.getInfo[6bdd016a-c722-4ed5-af1f-af7de2bbb2f7]  
[2020-11-26 18:26:13,879: INFO/ForkPoolWorker-1] Task tempsens.tasks.getInfo[6bdd016a-c722-4ed5-af1f-af7de2bbb2f7] succeeded in 0.5474663649947615s: {'temp': 24.0, 'hum': 53.0}
/home/pi/rpi_temp/django_app/tempsens/tasks.py:11: RuntimeWarning: This channel is already in use, continuing anyway.  Use GPIO.setwarnings(False) to disable warnings.
  GPIO.setup(led, GPIO.OUT)
[2020-11-26 18:32:59,707: ERROR/MainProcess] consumer: Cannot connect to redis://localhost:6379//: Error 111 connecting to localhost:6379. Connection refused..
Trying again in 2.00 seconds... (1/100)

[2020-11-26 18:33:01,766: ERROR/MainProcess] consumer: Cannot connect to redis://localhost:6379//: Error 111 connecting to localhost:6379. Connection refused..
Trying again in 4.00 seconds... (2/100)

[2020-11-26 18:33:05,804: ERROR/MainProcess] consumer: Cannot connect to redis://localhost:6379//: Error 111 connecting to localhost:6379. Connection refused..
Trying again in 6.00 seconds... (3/100)

[2020-11-26 18:33:11,849: ERROR/MainProcess] consumer: Cannot connect to redis://localhost:6379//: Error 111 connecting to localhost:6379. Connection refused..
Trying again in 8.00 seconds... (4/100)

[2020-11-26 18:33:19,925: ERROR/MainProcess] consumer: Cannot connect to redis://localhost:6379//: Error 111 connecting to localhost:6379. Connection refused..
Trying again in 10.00 seconds... (5/100)

[2020-11-26 18:33:29,989: ERROR/MainProcess] consumer: Cannot connect to redis://localhost:6379//: Error 111 connecting to localhost:6379. Connection refused..
Trying again in 12.00 seconds... (6/100)

[2020-11-26 18:33:42,047: ERROR/MainProcess] consumer: Cannot connect to redis://localhost:6379//: Error 111 connecting to localhost:6379. Connection refused..
Trying again in 14.00 seconds... (7/100)

