Watching for file changes with StatReloader
/home/pi/rpi_temp/tempsens/tasks.py:11: RuntimeWarning: This channel is already in use, continuing anyway.  Use GPIO.setwarnings(False) to disable warnings.
  GPIO.setup(led, GPIO.OUT)
[17/Nov/2020 18:06:14] "GET /tempsens/ HTTP/1.1" 200 1456
[17/Nov/2020 18:06:14] "GET /static/tempsens/css/style.css HTTP/1.1" 200 974
[17/Nov/2020 18:06:14] "GET /static/tempsens/favicon.ico HTTP/1.1" 200 1065
[17/Nov/2020 18:06:21] "GET /tempsens/get_data_json/ HTTP/1.1" 200 27
[17/Nov/2020 18:06:25] "GET /tempsens/power_led/? HTTP/1.1" 302 0
[17/Nov/2020 18:06:25] "GET /tempsens/ HTTP/1.1" 200 1456
[17/Nov/2020 18:06:27] "GET /tempsens/power_led/? HTTP/1.1" 302 0
[17/Nov/2020 18:06:31] "GET /tempsens/ HTTP/1.1" 200 1456
[17/Nov/2020 18:06:32] "GET /tempsens/power_led/? HTTP/1.1" 302 0
[17/Nov/2020 18:06:33] "GET /tempsens/ HTTP/1.1" 200 1456
[17/Nov/2020 18:06:40] "GET /tempsens/get_data_json/ HTTP/1.1" 200 27
[17/Nov/2020 18:07:07] "GET /tempsens/power_led/? HTTP/1.1" 302 0
[17/Nov/2020 18:07:08] "GET /tempsens/ HTTP/1.1" 200 1456
[17/Nov/2020 18:07:15] "GET /tempsens/disable_led/? HTTP/1.1" 302 0
[17/Nov/2020 18:07:21] "GET /tempsens/ HTTP/1.1" 200 1456
[17/Nov/2020 18:42:42] "GET /static/tempsens/icon/temp_icon.png HTTP/1.1" 404 1706
[17/Nov/2020 21:38:09] "GET /static/tempsens/icon/temp_icon.png HTTP/1.1" 404 1706
[17/Nov/2020 21:38:10] "GET /static/tempsens/icon/temp_icon.png HTTP/1.1" 404 1706
[17/Nov/2020 21:38:16] "GET /static/tempsens/icon/temp_icon.png HTTP/1.1" 404 1706
[17/Nov/2020 22:00:50] "GET /static/tempsens/icon/temp_icon.png HTTP/1.1" 404 1706
[19/Nov/2020 17:54:18] "GET /static/tempsens/favicon.ico HTTP/1.1" 200 1065
[19/Nov/2020 17:54:20] "GET /static/tempsens/icon/temp_icon.png HTTP/1.1" 404 1706
[19/Nov/2020 17:54:20] "GET /static/tempsens/icon/temp_icon.png HTTP/1.1" 404 1706
[19/Nov/2020 17:54:25] "GET /static/tempsens/icon/temp_icon.png HTTP/1.1" 404 1706
[20/Nov/2020 14:53:55] "GET /static/tempsens/icon/temp_icon.png HTTP/1.1" 404 1706
[20/Nov/2020 14:54:00] "GET /static/tempsens/icon/temp_icon.png HTTP/1.1" 404 1706
[20/Nov/2020 14:59:10] "GET /tempsens/ HTTP/1.1" 200 1456
[20/Nov/2020 14:59:16] "GET /tempsens/get_data_json/ HTTP/1.1" 200 27
----------------------------------------
Exception happened during processing of request from ('192.168.0.172', 52867)
----------------------------------------
Exception happened during processing of request from ('192.168.0.172', 52866)
Traceback (most recent call last):
  File "/usr/lib/python3.7/socketserver.py", line 650, in process_request_thread
    self.finish_request(request, client_address)
  File "/usr/lib/python3.7/socketserver.py", line 360, in finish_request
    self.RequestHandlerClass(request, client_address, self)
  File "/usr/lib/python3.7/socketserver.py", line 720, in __init__
    self.handle()
  File "/usr/local/lib/python3.7/dist-packages/django/core/servers/basehttp.py", line 174, in handle
    self.handle_one_request()
  File "/usr/local/lib/python3.7/dist-packages/django/core/servers/basehttp.py", line 182, in handle_one_request
    self.raw_requestline = self.rfile.readline(65537)
  File "/usr/lib/python3.7/socket.py", line 589, in readinto
    return self._sock.recv_into(b)
ConnectionResetError: [Errno 104] Connection reset by peer
----------------------------------------
Traceback (most recent call last):
  File "/usr/lib/python3.7/socketserver.py", line 650, in process_request_thread
    self.finish_request(request, client_address)
  File "/usr/lib/python3.7/socketserver.py", line 360, in finish_request
    self.RequestHandlerClass(request, client_address, self)
  File "/usr/lib/python3.7/socketserver.py", line 720, in __init__
    self.handle()
  File "/usr/local/lib/python3.7/dist-packages/django/core/servers/basehttp.py", line 172, in handle
    self.handle_one_request()
  File "/usr/local/lib/python3.7/dist-packages/django/core/servers/basehttp.py", line 182, in handle_one_request
    self.raw_requestline = self.rfile.readline(65537)
  File "/usr/lib/python3.7/socket.py", line 589, in readinto
    return self._sock.recv_into(b)
ConnectionResetError: [Errno 104] Connection reset by peer
----------------------------------------
[21/Nov/2020 13:54:17] "GET /tempsens/ HTTP/1.1" 200 1456
[21/Nov/2020 13:54:21] "GET /static/tempsens/icon/temp_icon.png HTTP/1.1" 404 1706
[21/Nov/2020 14:48:40] "GET /static/tempsens/icon/temp_icon.png HTTP/1.1" 404 1706
[21/Nov/2020 14:48:40] "GET /static/tempsens/icon/temp_icon.png HTTP/1.1" 404 1706
[21/Nov/2020 14:48:46] "GET /static/tempsens/icon/temp_icon.png HTTP/1.1" 404 1706
[21/Nov/2020 15:13:43] "GET /static/tempsens/icon/temp_icon.png HTTP/1.1" 404 1706
Not Found: /favicon.ico
[21/Nov/2020 15:13:44] "GET /favicon.ico HTTP/1.1" 404 2086
[21/Nov/2020 15:47:29] "GET /static/tempsens/icon/temp_icon.png HTTP/1.1" 404 1706
[21/Nov/2020 15:57:24] "GET /static/tempsens/icon/temp_icon.png HTTP/1.1" 404 1706
[21/Nov/2020 16:00:32] "GET /static/tempsens/icon/temp_icon.png HTTP/1.1" 404 1706
[22/Nov/2020 03:00:31] "GET /static/tempsens/icon/temp_icon.png HTTP/1.1" 404 1706
[22/Nov/2020 03:00:35] "GET /static/tempsens/icon/temp_icon.png HTTP/1.1" 404 1706
[22/Nov/2020 18:20:55] "GET /static/tempsens/icon/temp_icon.png HTTP/1.1" 404 1706
[22/Nov/2020 18:20:56] "GET /static/tempsens/icon/temp_icon.png HTTP/1.1" 404 1706
[23/Nov/2020 19:48:22] "GET /tempsens/ HTTP/1.1" 200 1456
[23/Nov/2020 19:48:24] "GET /static/tempsens/js/script.js HTTP/1.1" 200 774
[23/Nov/2020 19:48:24] "GET /static/tempsens/css/style.css HTTP/1.1" 200 974
[23/Nov/2020 19:48:25] "GET /static/tempsens/favicon.ico HTTP/1.1" 200 1065
[23/Nov/2020 19:48:36] "GET /tempsens/power_led/? HTTP/1.1" 302 0
Internal Server Error: /tempsens/get_data_json/
Traceback (most recent call last):
  File "/usr/local/lib/python3.7/dist-packages/django/core/handlers/exception.py", line 34, in inner
    response = get_response(request)
  File "/usr/local/lib/python3.7/dist-packages/django/core/handlers/base.py", line 115, in _get_response
    response = self.process_exception_by_middleware(e, request)
  File "/usr/local/lib/python3.7/dist-packages/django/core/handlers/base.py", line 113, in _get_response
    response = wrapped_callback(request, *callback_args, **callback_kwargs)
  File "/home/pi/rpi_temp/tempsens/views.py", line 28, in get_data_json
    info = task_result.get()
  File "/usr/local/lib/python3.7/dist-packages/celery/result.py", line 228, in get
    on_message=on_message,
  File "/usr/local/lib/python3.7/dist-packages/celery/backends/asynchronous.py", line 202, in wait_for_pending
    return result.maybe_throw(callback=callback, propagate=propagate)
  File "/usr/local/lib/python3.7/dist-packages/celery/result.py", line 333, in maybe_throw
    self.throw(value, self._to_remote_traceback(tb))
  File "/usr/local/lib/python3.7/dist-packages/celery/result.py", line 326, in throw
    self.on_ready.throw(*args, **kwargs)
  File "/usr/local/lib/python3.7/dist-packages/vine/promises.py", line 244, in throw
    reraise(type(exc), exc, tb)
  File "/usr/local/lib/python3.7/dist-packages/vine/five.py", line 195, in reraise
    raise value
TypeError: '<' not supported between instances of 'NoneType' and 'int'
[23/Nov/2020 19:49:08] "GET /tempsens/get_data_json/ HTTP/1.1" 500 15063
Internal Server Error: /tempsens/get_data_json/
Traceback (most recent call last):
  File "/usr/local/lib/python3.7/dist-packages/django/core/handlers/exception.py", line 34, in inner
    response = get_response(request)
  File "/usr/local/lib/python3.7/dist-packages/django/core/handlers/base.py", line 115, in _get_response
    response = self.process_exception_by_middleware(e, request)
  File "/usr/local/lib/python3.7/dist-packages/django/core/handlers/base.py", line 113, in _get_response
    response = wrapped_callback(request, *callback_args, **callback_kwargs)
  File "/home/pi/rpi_temp/tempsens/views.py", line 28, in get_data_json
    info = task_result.get()
  File "/usr/local/lib/python3.7/dist-packages/celery/result.py", line 228, in get
    on_message=on_message,
  File "/usr/local/lib/python3.7/dist-packages/celery/backends/asynchronous.py", line 202, in wait_for_pending
    return result.maybe_throw(callback=callback, propagate=propagate)
  File "/usr/local/lib/python3.7/dist-packages/celery/result.py", line 333, in maybe_throw
    self.throw(value, self._to_remote_traceback(tb))
  File "/usr/local/lib/python3.7/dist-packages/celery/result.py", line 326, in throw
    self.on_ready.throw(*args, **kwargs)
  File "/usr/local/lib/python3.7/dist-packages/vine/promises.py", line 244, in throw
    reraise(type(exc), exc, tb)
  File "/usr/local/lib/python3.7/dist-packages/vine/five.py", line 195, in reraise
    raise value
TypeError: '<' not supported between instances of 'NoneType' and 'int'
[23/Nov/2020 19:49:10] "GET /tempsens/get_data_json/ HTTP/1.1" 500 15063
Internal Server Error: /tempsens/
Traceback (most recent call last):
  File "/usr/local/lib/python3.7/dist-packages/django/core/handlers/exception.py", line 34, in inner
    response = get_response(request)
  File "/usr/local/lib/python3.7/dist-packages/django/core/handlers/base.py", line 115, in _get_response
    response = self.process_exception_by_middleware(e, request)
  File "/usr/local/lib/python3.7/dist-packages/django/core/handlers/base.py", line 113, in _get_response
    response = wrapped_callback(request, *callback_args, **callback_kwargs)
  File "/usr/local/lib/python3.7/dist-packages/django/views/generic/base.py", line 71, in view
    return self.dispatch(request, *args, **kwargs)
  File "/usr/local/lib/python3.7/dist-packages/django/views/generic/base.py", line 97, in dispatch
    return handler(request, *args, **kwargs)
  File "/home/pi/rpi_temp/tempsens/views.py", line 11, in get
    info = task_result.get()
  File "/usr/local/lib/python3.7/dist-packages/celery/result.py", line 228, in get
    on_message=on_message,
  File "/usr/local/lib/python3.7/dist-packages/celery/backends/asynchronous.py", line 202, in wait_for_pending
    return result.maybe_throw(callback=callback, propagate=propagate)
  File "/usr/local/lib/python3.7/dist-packages/celery/result.py", line 333, in maybe_throw
    self.throw(value, self._to_remote_traceback(tb))
  File "/usr/local/lib/python3.7/dist-packages/celery/result.py", line 326, in throw
    self.on_ready.throw(*args, **kwargs)
  File "/usr/local/lib/python3.7/dist-packages/vine/promises.py", line 244, in throw
    reraise(type(exc), exc, tb)
  File "/usr/local/lib/python3.7/dist-packages/vine/five.py", line 195, in reraise
    raise value
TypeError: '<' not supported between instances of 'NoneType' and 'int'
[23/Nov/2020 19:49:46] "GET /tempsens/ HTTP/1.1" 500 103819
Internal Server Error: /tempsens/
Traceback (most recent call last):
  File "/usr/local/lib/python3.7/dist-packages/django/core/handlers/exception.py", line 34, in inner
    response = get_response(request)
  File "/usr/local/lib/python3.7/dist-packages/django/core/handlers/base.py", line 115, in _get_response
    response = self.process_exception_by_middleware(e, request)
  File "/usr/local/lib/python3.7/dist-packages/django/core/handlers/base.py", line 113, in _get_response
    response = wrapped_callback(request, *callback_args, **callback_kwargs)
  File "/usr/local/lib/python3.7/dist-packages/django/views/generic/base.py", line 71, in view
    return self.dispatch(request, *args, **kwargs)
  File "/usr/local/lib/python3.7/dist-packages/django/views/generic/base.py", line 97, in dispatch
    return handler(request, *args, **kwargs)
  File "/home/pi/rpi_temp/tempsens/views.py", line 11, in get
    info = task_result.get()
  File "/usr/local/lib/python3.7/dist-packages/celery/result.py", line 228, in get
    on_message=on_message,
  File "/usr/local/lib/python3.7/dist-packages/celery/backends/asynchronous.py", line 202, in wait_for_pending
    return result.maybe_throw(callback=callback, propagate=propagate)
  File "/usr/local/lib/python3.7/dist-packages/celery/result.py", line 333, in maybe_throw
    self.throw(value, self._to_remote_traceback(tb))
  File "/usr/local/lib/python3.7/dist-packages/celery/result.py", line 326, in throw
    self.on_ready.throw(*args, **kwargs)
  File "/usr/local/lib/python3.7/dist-packages/vine/promises.py", line 244, in throw
    reraise(type(exc), exc, tb)
  File "/usr/local/lib/python3.7/dist-packages/vine/five.py", line 195, in reraise
    raise value
TypeError: '<' not supported between instances of 'NoneType' and 'int'
[23/Nov/2020 19:49:50] "GET /tempsens/ HTTP/1.1" 500 103667
Not Found: /favicon.ico
[23/Nov/2020 19:49:50] "GET /favicon.ico HTTP/1.1" 404 2086
[23/Nov/2020 19:51:51] "GET /tempsens/ HTTP/1.1" 200 1456
[23/Nov/2020 19:52:16] "GET /tempsens/ HTTP/1.1" 200 1456
[23/Nov/2020 19:52:16] "GET /static/tempsens/js/script.js HTTP/1.1" 304 0
[23/Nov/2020 19:52:16] "GET /static/tempsens/css/style.css HTTP/1.1" 304 0
[23/Nov/2020 19:52:24] "GET /tempsens/get_data_json/ HTTP/1.1" 200 27
[23/Nov/2020 19:52:27] "GET /tempsens/power_led/? HTTP/1.1" 302 0
[23/Nov/2020 19:52:31] "GET /tempsens/ HTTP/1.1" 200 1456
[23/Nov/2020 21:21:40] "GET /static/tempsens/icon/temp_icon.png HTTP/1.1" 404 1706
[23/Nov/2020 21:21:42] "GET /static/tempsens/icon/temp_icon.png HTTP/1.1" 404 1706
[23/Nov/2020 21:21:48] "GET /static/tempsens/icon/temp_icon.png HTTP/1.1" 404 1706
[23/Nov/2020 21:21:49] "GET /static/tempsens/icon/temp_icon.png HTTP/1.1" 404 1706
[23/Nov/2020 21:22:01] "GET /static/tempsens/icon/temp_icon.png HTTP/1.1" 404 1706
[23/Nov/2020 21:25:11] "GET /static/tempsens/icon/temp_icon.png HTTP/1.1" 404 1706
[25/Nov/2020 11:30:45] "GET /static/tempsens/icon/temp_icon.png HTTP/1.1" 404 1706
[25/Nov/2020 11:31:29] "GET /static/tempsens/icon/temp_icon.png HTTP/1.1" 404 1706
[25/Nov/2020 11:31:33] "GET /static/tempsens/icon/temp_icon.png HTTP/1.1" 404 1706
[25/Nov/2020 11:33:50] "GET /static/tempsens/icon/temp_icon.png HTTP/1.1" 404 1706
[25/Nov/2020 11:43:10] "GET /static/tempsens/icon/temp_icon.png HTTP/1.1" 404 1706
[25/Nov/2020 11:48:42] "GET /static/tempsens/icon/temp_icon.png HTTP/1.1" 404 1706
[25/Nov/2020 11:57:07] "GET /static/tempsens/icon/temp_icon.png HTTP/1.1" 404 1706
[25/Nov/2020 11:57:13] "GET /static/tempsens/icon/temp_icon.png HTTP/1.1" 404 1706
Not Found: /
[25/Nov/2020 16:18:51] "GET / HTTP/1.1" 404 2035
Not Found: /favicon.ico
[25/Nov/2020 16:18:51] "GET /favicon.ico HTTP/1.1" 404 2086
