 * Serving Flask app "main" (lazy loading)
 * Environment: production
   WARNING: Do not use the development server in a production environment.
   Use a production WSGI server instead.
 * Debug mode: off
 * Serving Flask app "main" (lazy loading)
 * Environment: production
   WARNING: Do not use the development server in a production environment.
   Use a production WSGI server instead.
 * Debug mode: off
 * Serving Flask app "main" (lazy loading)
 * Environment: production
   WARNING: Do not use the development server in a production environment.
   Use a production WSGI server instead.
 * Debug mode: off
/home/pi/rpi_temp/flask_app/rpi/rpi_setup.py:10: RuntimeWarning: This channel is already in use, continuing anyway.  Use GPIO.setwarnings(False) to disable warnings.
  GPIO.setup(led, GPIO.OUT)
 * Running on http://192.168.0.107:80/ (Press CTRL+C to quit)
 * Serving Flask app "main" (lazy loading)
 * Environment: production
   WARNING: Do not use the development server in a production environment.
   Use a production WSGI server instead.
 * Debug mode: off
/home/pi/rpi_temp/flask_app/rpi/rpi_setup.py:10: RuntimeWarning: This channel is already in use, continuing anyway.  Use GPIO.setwarnings(False) to disable warnings.
  GPIO.setup(led, GPIO.OUT)
 * Running on http://192.168.0.107:80/ (Press CTRL+C to quit)
 * Serving Flask app "main" (lazy loading)
 * Environment: production
   WARNING: Do not use the development server in a production environment.
   Use a production WSGI server instead.
 * Debug mode: off
/home/pi/rpi_temp/flask_app/rpi/rpi_setup.py:10: RuntimeWarning: This channel is already in use, continuing anyway.  Use GPIO.setwarnings(False) to disable warnings.
  GPIO.setup(led, GPIO.OUT)
 * Running on http://192.168.0.107:80/ (Press CTRL+C to quit)
192.168.0.169 - - [08/Feb/2021 17:32:47] "GET /tempsens HTTP/1.1" 200 -
192.168.0.169 - - [08/Feb/2021 17:32:47] "GET /static/js/script.js HTTP/1.1" 200 -
192.168.0.169 - - [08/Feb/2021 17:32:47] "GET /static/css/style.css HTTP/1.1" 200 -
192.168.0.169 - - [08/Feb/2021 17:32:52] "POST /tempsens/power_led HTTP/1.1" 201 -
192.168.0.169 - - [08/Feb/2021 17:32:54] "POST /tempsens/power_led HTTP/1.1" 201 -
192.168.0.169 - - [08/Feb/2021 17:32:54] "POST /tempsens/disable_led HTTP/1.1" 201 -
192.168.0.169 - - [08/Feb/2021 17:32:56] "POST /tempsens/power_led HTTP/1.1" 201 -
192.168.0.169 - - [08/Feb/2021 17:32:57] "POST /tempsens/disable_led HTTP/1.1" 201 -
192.168.0.169 - - [08/Feb/2021 17:32:59] "POST /tempsens/get_data_json HTTP/1.1" 200 -
 * Serving Flask app "main" (lazy loading)
 * Environment: production
   WARNING: Do not use the development server in a production environment.
   Use a production WSGI server instead.
 * Debug mode: off
/home/pi/rpi_temp/flask_app/rpi/rpi_setup.py:10: RuntimeWarning: This channel is already in use, continuing anyway.  Use GPIO.setwarnings(False) to disable warnings.
  GPIO.setup(led, GPIO.OUT)
 * Running on http://192.168.0.107:80/ (Press CTRL+C to quit)
192.168.0.169 - - [08/Feb/2021 17:40:12] "GET /tempsens HTTP/1.1" 200 -
192.168.0.169 - - [08/Feb/2021 17:40:13] "GET /static/js/script.js HTTP/1.1" 200 -
192.168.0.169 - - [08/Feb/2021 17:40:13] "GET /static/css/style.css HTTP/1.1" 200 -
192.168.0.169 - - [08/Feb/2021 17:40:23] "POST /tempsens/power_led HTTP/1.1" 201 -
192.168.0.169 - - [08/Feb/2021 17:40:25] "POST /tempsens/disable_led HTTP/1.1" 201 -
192.168.0.169 - - [08/Feb/2021 17:41:31] "GET /tempsens HTTP/1.1" 200 -
192.168.0.169 - - [08/Feb/2021 17:41:31] "GET /static/css/style.css HTTP/1.1" 200 -
192.168.0.169 - - [08/Feb/2021 17:41:31] "GET /static/js/script.js HTTP/1.1" 200 -
192.168.0.169 - - [08/Feb/2021 17:41:34] "GET /tempsens HTTP/1.1" 200 -
192.168.0.169 - - [08/Feb/2021 17:41:34] "GET /static/css/style.css HTTP/1.1" 200 -
192.168.0.169 - - [08/Feb/2021 17:41:34] "GET /static/js/script.js HTTP/1.1" 200 -
192.168.0.169 - - [08/Feb/2021 18:40:44] "GET /tempsens HTTP/1.1" 200 -
192.168.0.169 - - [08/Feb/2021 18:40:49] "GET /tempsens HTTP/1.1" 200 -
192.168.0.169 - - [08/Feb/2021 18:40:53] "POST /tempsens/get_data_json HTTP/1.1" 200 -
192.168.0.169 - - [08/Feb/2021 18:58:46] "GET /tempsens HTTP/1.1" 200 -
192.168.0.169 - - [08/Feb/2021 18:58:50] "POST /tempsens/get_data_json HTTP/1.1" 200 -
192.168.0.169 - - [09/Feb/2021 00:49:38] "GET /tempsens HTTP/1.1" 200 -
192.168.0.169 - - [09/Feb/2021 00:49:41] "GET /tempsens HTTP/1.1" 200 -
192.168.0.169 - - [09/Feb/2021 00:49:46] "POST /tempsens/get_data_json HTTP/1.1" 200 -
192.168.0.169 - - [09/Feb/2021 00:49:49] "POST /tempsens/get_data_json HTTP/1.1" 200 -
192.168.0.169 - - [09/Feb/2021 00:54:52] "GET /static/favicon.ico HTTP/1.1" 200 -
192.168.0.169 - - [09/Feb/2021 00:54:53] "GET /tempsens HTTP/1.1" 200 -
192.168.0.169 - - [09/Feb/2021 00:56:25] "GET /tempsens HTTP/1.1" 200 -
192.168.0.169 - - [09/Feb/2021 01:22:26] "GET /tempsens HTTP/1.1" 200 -
192.168.0.169 - - [09/Feb/2021 01:22:26] "GET /static/css/style.css HTTP/1.1" 200 -
192.168.0.169 - - [09/Feb/2021 01:22:26] "GET /static/js/script.js HTTP/1.1" 200 -
192.168.0.169 - - [09/Feb/2021 17:04:52] "GET /tempsens HTTP/1.1" 200 -
192.168.0.169 - - [09/Feb/2021 17:04:52] "GET /static/js/script.js HTTP/1.1" 304 -
192.168.0.169 - - [09/Feb/2021 17:04:52] "GET /static/css/style.css HTTP/1.1" 304 -
192.168.0.169 - - [09/Feb/2021 17:08:27] "GET /tempsens HTTP/1.1" 200 -
192.168.0.169 - - [09/Feb/2021 17:29:10] "GET /tempsens HTTP/1.1" 200 -
192.168.0.129 - - [10/Feb/2021 19:41:18] "GET /tempsens HTTP/1.1" 200 -
192.168.0.129 - - [10/Feb/2021 19:41:18] "GET /static/css/style.css HTTP/1.1" 200 -
192.168.0.129 - - [10/Feb/2021 19:41:18] "GET /static/js/script.js HTTP/1.1" 200 -
192.168.0.129 - - [10/Feb/2021 19:41:18] "GET /static/favicon.ico HTTP/1.1" 200 -
192.168.0.129 - - [10/Feb/2021 19:41:20] "POST /tempsens/power_led HTTP/1.1" 201 -
192.168.0.129 - - [10/Feb/2021 19:41:21] "POST /tempsens/disable_led HTTP/1.1" 201 -
192.168.0.129 - - [10/Feb/2021 19:41:22] "POST /tempsens/power_led HTTP/1.1" 201 -
192.168.0.129 - - [10/Feb/2021 19:41:23] "POST /tempsens/disable_led HTTP/1.1" 201 -
192.168.0.129 - - [10/Feb/2021 19:41:25] "POST /tempsens/get_data_json HTTP/1.1" 200 -
192.168.0.129 - - [10/Feb/2021 19:41:30] "POST /tempsens/get_data_json HTTP/1.1" 200 -
192.168.0.129 - - [10/Feb/2021 19:41:35] "POST /tempsens/get_data_json HTTP/1.1" 200 -
192.168.0.129 - - [10/Feb/2021 19:41:38] "POST /tempsens/power_led HTTP/1.1" 201 -
192.168.0.129 - - [10/Feb/2021 19:41:39] "POST /tempsens/disable_led HTTP/1.1" 201 -
192.168.0.129 - - [10/Feb/2021 19:41:42] "POST /tempsens/power_led HTTP/1.1" 201 -
192.168.0.129 - - [10/Feb/2021 19:41:43] "POST /tempsens/power_led HTTP/1.1" 201 -
192.168.0.129 - - [10/Feb/2021 19:41:44] "POST /tempsens/power_led HTTP/1.1" 201 -
192.168.0.129 - - [10/Feb/2021 19:41:45] "POST /tempsens/power_led HTTP/1.1" 201 -
192.168.0.129 - - [10/Feb/2021 19:41:46] "POST /tempsens/power_led HTTP/1.1" 201 -
192.168.0.129 - - [10/Feb/2021 19:41:47] "POST /tempsens/disable_led HTTP/1.1" 201 -
192.168.0.129 - - [10/Feb/2021 19:41:49] "POST /tempsens/get_data_json HTTP/1.1" 200 -
192.168.0.129 - - [10/Feb/2021 19:41:51] "POST /tempsens/get_data_json HTTP/1.1" 200 -
192.168.0.129 - - [10/Feb/2021 19:41:52] "POST /tempsens/get_data_json HTTP/1.1" 200 -
192.168.0.129 - - [10/Feb/2021 19:41:55] "POST /tempsens/get_data_json HTTP/1.1" 200 -
192.168.0.129 - - [10/Feb/2021 19:43:14] "POST /tempsens/power_led HTTP/1.1" 201 -
192.168.0.129 - - [10/Feb/2021 19:43:15] "POST /tempsens/disable_led HTTP/1.1" 201 -
192.168.0.129 - - [10/Feb/2021 19:43:17] "POST /tempsens/power_led HTTP/1.1" 201 -
192.168.0.129 - - [10/Feb/2021 19:43:17] "POST /tempsens/disable_led HTTP/1.1" 201 -
192.168.0.129 - - [10/Feb/2021 19:43:18] "POST /tempsens/power_led HTTP/1.1" 201 -
192.168.0.129 - - [10/Feb/2021 19:43:19] "POST /tempsens/get_data_json HTTP/1.1" 200 -
192.168.0.169 - - [13/Feb/2021 18:11:26] "GET /tempsens HTTP/1.1" 200 -
192.168.0.169 - - [13/Feb/2021 18:11:27] "GET /static/css/style.css HTTP/1.1" 304 -
192.168.0.169 - - [13/Feb/2021 18:11:27] "GET /static/js/script.js HTTP/1.1" 304 -
192.168.0.169 - - [13/Feb/2021 18:11:33] "POST /tempsens/get_data_json HTTP/1.1" 200 -
192.168.0.169 - - [13/Feb/2021 18:12:00] "GET /tempsens HTTP/1.1" 200 -
192.168.0.187 - - [13/Feb/2021 22:04:28] "GET /tempsens HTTP/1.1" 200 -
[2021-02-13 22:05:32,865] ERROR in app: Exception on /tempsens [GET]
Traceback (most recent call last):
  File "/usr/lib/python3/dist-packages/flask/app.py", line 1974, in make_response
    rv = self.response_class.force_type(rv, request.environ)
  File "/usr/lib/python3/dist-packages/werkzeug/wrappers.py", line 921, in force_type
    response = BaseResponse(*_run_wsgi_app(response, environ))
  File "/usr/lib/python3/dist-packages/werkzeug/wrappers.py", line 59, in _run_wsgi_app
    return _run_wsgi_app(*args)
  File "/usr/lib/python3/dist-packages/werkzeug/test.py", line 923, in run_wsgi_app
    app_rv = app(environ, start_response)
TypeError: 'dict' object is not callable

During handling of the above exception, another exception occurred:

Traceback (most recent call last):
  File "/usr/lib/python3/dist-packages/flask/app.py", line 2292, in wsgi_app
    response = self.full_dispatch_request()
  File "/usr/lib/python3/dist-packages/flask/app.py", line 1816, in full_dispatch_request
    return self.finalize_request(rv)
  File "/usr/lib/python3/dist-packages/flask/app.py", line 1831, in finalize_request
    response = self.make_response(rv)
  File "/usr/lib/python3/dist-packages/flask/app.py", line 1982, in make_response
    reraise(TypeError, new_error, sys.exc_info()[2])
  File "/usr/lib/python3/dist-packages/flask/_compat.py", line 34, in reraise
    raise value.with_traceback(tb)
  File "/usr/lib/python3/dist-packages/flask/app.py", line 1974, in make_response
    rv = self.response_class.force_type(rv, request.environ)
  File "/usr/lib/python3/dist-packages/werkzeug/wrappers.py", line 921, in force_type
    response = BaseResponse(*_run_wsgi_app(response, environ))
  File "/usr/lib/python3/dist-packages/werkzeug/wrappers.py", line 59, in _run_wsgi_app
    return _run_wsgi_app(*args)
  File "/usr/lib/python3/dist-packages/werkzeug/test.py", line 923, in run_wsgi_app
    app_rv = app(environ, start_response)
TypeError: 'dict' object is not callable
The view function did not return a valid response. The return type must be a string, tuple, Response instance, or WSGI callable, but it was a dict.
192.168.0.187 - - [13/Feb/2021 22:05:33] "GET /tempsens HTTP/1.1" 500 -
Error on request:
Traceback (most recent call last):
  File "/usr/lib/python3/dist-packages/werkzeug/serving.py", line 270, in run_wsgi
    execute(self.server.app)
  File "/usr/lib/python3/dist-packages/werkzeug/serving.py", line 258, in execute
    application_iter = app(environ, start_response)
  File "/usr/lib/python3/dist-packages/flask/app.py", line 2309, in __call__
    return self.wsgi_app(environ, start_response)
  File "/usr/lib/python3/dist-packages/flask/app.py", line 2295, in wsgi_app
    response = self.handle_exception(e)
  File "/usr/lib/python3/dist-packages/flask/app.py", line 1748, in handle_exception
    return self.finalize_request(handler(e), from_error_handler=True)
  File "/usr/lib/python3/dist-packages/flask/app.py", line 1831, in finalize_request
    response = self.make_response(rv)
  File "/usr/lib/python3/dist-packages/flask/app.py", line 1982, in make_response
    reraise(TypeError, new_error, sys.exc_info()[2])
  File "/usr/lib/python3/dist-packages/flask/_compat.py", line 34, in reraise
    raise value.with_traceback(tb)
  File "/usr/lib/python3/dist-packages/flask/app.py", line 1974, in make_response
    rv = self.response_class.force_type(rv, request.environ)
  File "/usr/lib/python3/dist-packages/werkzeug/wrappers.py", line 921, in force_type
    response = BaseResponse(*_run_wsgi_app(response, environ))
  File "/usr/lib/python3/dist-packages/werkzeug/test.py", line 923, in run_wsgi_app
    app_rv = app(environ, start_response)
TypeError: 'dict' object is not callable
The view function did not return a valid response. The return type must be a string, tuple, Response instance, or WSGI callable, but it was a dict.
[2021-02-13 22:05:33,596] ERROR in app: Exception on /favicon.ico [GET]
Traceback (most recent call last):
  File "/usr/lib/python3/dist-packages/flask/app.py", line 1974, in make_response
    rv = self.response_class.force_type(rv, request.environ)
  File "/usr/lib/python3/dist-packages/werkzeug/wrappers.py", line 921, in force_type
    response = BaseResponse(*_run_wsgi_app(response, environ))
  File "/usr/lib/python3/dist-packages/werkzeug/test.py", line 923, in run_wsgi_app
    app_rv = app(environ, start_response)
TypeError: 'dict' object is not callable

During handling of the above exception, another exception occurred:

Traceback (most recent call last):
  File "/usr/lib/python3/dist-packages/flask/app.py", line 2292, in wsgi_app
    response = self.full_dispatch_request()
  File "/usr/lib/python3/dist-packages/flask/app.py", line 1816, in full_dispatch_request
    return self.finalize_request(rv)
  File "/usr/lib/python3/dist-packages/flask/app.py", line 1831, in finalize_request
    response = self.make_response(rv)
  File "/usr/lib/python3/dist-packages/flask/app.py", line 1982, in make_response
    reraise(TypeError, new_error, sys.exc_info()[2])
  File "/usr/lib/python3/dist-packages/flask/_compat.py", line 34, in reraise
    raise value.with_traceback(tb)
  File "/usr/lib/python3/dist-packages/flask/app.py", line 1974, in make_response
    rv = self.response_class.force_type(rv, request.environ)
  File "/usr/lib/python3/dist-packages/werkzeug/wrappers.py", line 921, in force_type
    response = BaseResponse(*_run_wsgi_app(response, environ))
  File "/usr/lib/python3/dist-packages/werkzeug/test.py", line 923, in run_wsgi_app
    app_rv = app(environ, start_response)
TypeError: 'dict' object is not callable
The view function did not return a valid response. The return type must be a string, tuple, Response instance, or WSGI callable, but it was a dict.
192.168.0.187 - - [13/Feb/2021 22:05:33] "GET /favicon.ico HTTP/1.1" 500 -
Error on request:
Traceback (most recent call last):
  File "/usr/lib/python3/dist-packages/werkzeug/serving.py", line 270, in run_wsgi
    execute(self.server.app)
  File "/usr/lib/python3/dist-packages/werkzeug/serving.py", line 258, in execute
    application_iter = app(environ, start_response)
  File "/usr/lib/python3/dist-packages/flask/app.py", line 2309, in __call__
    return self.wsgi_app(environ, start_response)
  File "/usr/lib/python3/dist-packages/flask/app.py", line 2295, in wsgi_app
    response = self.handle_exception(e)
  File "/usr/lib/python3/dist-packages/flask/app.py", line 1748, in handle_exception
    return self.finalize_request(handler(e), from_error_handler=True)
  File "/usr/lib/python3/dist-packages/flask/app.py", line 1831, in finalize_request
    response = self.make_response(rv)
  File "/usr/lib/python3/dist-packages/flask/app.py", line 1982, in make_response
    reraise(TypeError, new_error, sys.exc_info()[2])
  File "/usr/lib/python3/dist-packages/flask/_compat.py", line 34, in reraise
    raise value.with_traceback(tb)
  File "/usr/lib/python3/dist-packages/flask/app.py", line 1974, in make_response
    rv = self.response_class.force_type(rv, request.environ)
  File "/usr/lib/python3/dist-packages/werkzeug/wrappers.py", line 921, in force_type
    response = BaseResponse(*_run_wsgi_app(response, environ))
  File "/usr/lib/python3/dist-packages/werkzeug/test.py", line 923, in run_wsgi_app
    app_rv = app(environ, start_response)
TypeError: 'dict' object is not callable
The view function did not return a valid response. The return type must be a string, tuple, Response instance, or WSGI callable, but it was a dict.
[2021-02-13 22:05:34,093] ERROR in app: Exception on /favicon.ico [GET]
Traceback (most recent call last):
  File "/usr/lib/python3/dist-packages/flask/app.py", line 1974, in make_response
    rv = self.response_class.force_type(rv, request.environ)
  File "/usr/lib/python3/dist-packages/werkzeug/wrappers.py", line 921, in force_type
    response = BaseResponse(*_run_wsgi_app(response, environ))
  File "/usr/lib/python3/dist-packages/werkzeug/test.py", line 923, in run_wsgi_app
    app_rv = app(environ, start_response)
TypeError: 'dict' object is not callable

During handling of the above exception, another exception occurred:

Traceback (most recent call last):
  File "/usr/lib/python3/dist-packages/flask/app.py", line 2292, in wsgi_app
    response = self.full_dispatch_request()
  File "/usr/lib/python3/dist-packages/flask/app.py", line 1816, in full_dispatch_request
    return self.finalize_request(rv)
  File "/usr/lib/python3/dist-packages/flask/app.py", line 1831, in finalize_request
    response = self.make_response(rv)
  File "/usr/lib/python3/dist-packages/flask/app.py", line 1982, in make_response
    reraise(TypeError, new_error, sys.exc_info()[2])
  File "/usr/lib/python3/dist-packages/flask/_compat.py", line 34, in reraise
    raise value.with_traceback(tb)
  File "/usr/lib/python3/dist-packages/flask/app.py", line 1974, in make_response
    rv = self.response_class.force_type(rv, request.environ)
  File "/usr/lib/python3/dist-packages/werkzeug/wrappers.py", line 921, in force_type
    response = BaseResponse(*_run_wsgi_app(response, environ))
  File "/usr/lib/python3/dist-packages/werkzeug/test.py", line 923, in run_wsgi_app
    app_rv = app(environ, start_response)
TypeError: 'dict' object is not callable
The view function did not return a valid response. The return type must be a string, tuple, Response instance, or WSGI callable, but it was a dict.
192.168.0.187 - - [13/Feb/2021 22:05:34] "GET /favicon.ico HTTP/1.1" 500 -
Error on request:
Traceback (most recent call last):
  File "/usr/lib/python3/dist-packages/werkzeug/serving.py", line 270, in run_wsgi
    execute(self.server.app)
  File "/usr/lib/python3/dist-packages/werkzeug/serving.py", line 258, in execute
    application_iter = app(environ, start_response)
  File "/usr/lib/python3/dist-packages/flask/app.py", line 2309, in __call__
    return self.wsgi_app(environ, start_response)
  File "/usr/lib/python3/dist-packages/flask/app.py", line 2295, in wsgi_app
    response = self.handle_exception(e)
  File "/usr/lib/python3/dist-packages/flask/app.py", line 1748, in handle_exception
    return self.finalize_request(handler(e), from_error_handler=True)
  File "/usr/lib/python3/dist-packages/flask/app.py", line 1831, in finalize_request
    response = self.make_response(rv)
  File "/usr/lib/python3/dist-packages/flask/app.py", line 1982, in make_response
    reraise(TypeError, new_error, sys.exc_info()[2])
  File "/usr/lib/python3/dist-packages/flask/_compat.py", line 34, in reraise
    raise value.with_traceback(tb)
  File "/usr/lib/python3/dist-packages/flask/app.py", line 1974, in make_response
    rv = self.response_class.force_type(rv, request.environ)
  File "/usr/lib/python3/dist-packages/werkzeug/wrappers.py", line 921, in force_type
    response = BaseResponse(*_run_wsgi_app(response, environ))
  File "/usr/lib/python3/dist-packages/werkzeug/test.py", line 923, in run_wsgi_app
    app_rv = app(environ, start_response)
TypeError: 'dict' object is not callable
The view function did not return a valid response. The return type must be a string, tuple, Response instance, or WSGI callable, but it was a dict.
[2021-02-13 22:05:34,601] ERROR in app: Exception on /favicon.ico [GET]
Traceback (most recent call last):
  File "/usr/lib/python3/dist-packages/flask/app.py", line 1974, in make_response
    rv = self.response_class.force_type(rv, request.environ)
  File "/usr/lib/python3/dist-packages/werkzeug/wrappers.py", line 921, in force_type
    response = BaseResponse(*_run_wsgi_app(response, environ))
  File "/usr/lib/python3/dist-packages/werkzeug/test.py", line 923, in run_wsgi_app
    app_rv = app(environ, start_response)
TypeError: 'dict' object is not callable

During handling of the above exception, another exception occurred:

Traceback (most recent call last):
  File "/usr/lib/python3/dist-packages/flask/app.py", line 2292, in wsgi_app
    response = self.full_dispatch_request()
  File "/usr/lib/python3/dist-packages/flask/app.py", line 1816, in full_dispatch_request
    return self.finalize_request(rv)
  File "/usr/lib/python3/dist-packages/flask/app.py", line 1831, in finalize_request
    response = self.make_response(rv)
  File "/usr/lib/python3/dist-packages/flask/app.py", line 1982, in make_response
    reraise(TypeError, new_error, sys.exc_info()[2])
  File "/usr/lib/python3/dist-packages/flask/_compat.py", line 34, in reraise
    raise value.with_traceback(tb)
  File "/usr/lib/python3/dist-packages/flask/app.py", line 1974, in make_response
    rv = self.response_class.force_type(rv, request.environ)
  File "/usr/lib/python3/dist-packages/werkzeug/wrappers.py", line 921, in force_type
    response = BaseResponse(*_run_wsgi_app(response, environ))
  File "/usr/lib/python3/dist-packages/werkzeug/test.py", line 923, in run_wsgi_app
    app_rv = app(environ, start_response)
TypeError: 'dict' object is not callable
The view function did not return a valid response. The return type must be a string, tuple, Response instance, or WSGI callable, but it was a dict.
192.168.0.187 - - [13/Feb/2021 22:05:34] "GET /favicon.ico HTTP/1.1" 500 -
Error on request:
Traceback (most recent call last):
  File "/usr/lib/python3/dist-packages/werkzeug/serving.py", line 270, in run_wsgi
    execute(self.server.app)
  File "/usr/lib/python3/dist-packages/werkzeug/serving.py", line 258, in execute
    application_iter = app(environ, start_response)
  File "/usr/lib/python3/dist-packages/flask/app.py", line 2309, in __call__
    return self.wsgi_app(environ, start_response)
  File "/usr/lib/python3/dist-packages/flask/app.py", line 2295, in wsgi_app
    response = self.handle_exception(e)
  File "/usr/lib/python3/dist-packages/flask/app.py", line 1748, in handle_exception
    return self.finalize_request(handler(e), from_error_handler=True)
  File "/usr/lib/python3/dist-packages/flask/app.py", line 1831, in finalize_request
    response = self.make_response(rv)
  File "/usr/lib/python3/dist-packages/flask/app.py", line 1982, in make_response
    reraise(TypeError, new_error, sys.exc_info()[2])
  File "/usr/lib/python3/dist-packages/flask/_compat.py", line 34, in reraise
    raise value.with_traceback(tb)
  File "/usr/lib/python3/dist-packages/flask/app.py", line 1974, in make_response
    rv = self.response_class.force_type(rv, request.environ)
  File "/usr/lib/python3/dist-packages/werkzeug/wrappers.py", line 921, in force_type
    response = BaseResponse(*_run_wsgi_app(response, environ))
  File "/usr/lib/python3/dist-packages/werkzeug/test.py", line 923, in run_wsgi_app
    app_rv = app(environ, start_response)
TypeError: 'dict' object is not callable
The view function did not return a valid response. The return type must be a string, tuple, Response instance, or WSGI callable, but it was a dict.
[2021-02-13 22:07:01,041] ERROR in app: Exception on /tempsens [GET]
Traceback (most recent call last):
  File "/usr/lib/python3/dist-packages/flask/app.py", line 1974, in make_response
    rv = self.response_class.force_type(rv, request.environ)
  File "/usr/lib/python3/dist-packages/werkzeug/wrappers.py", line 921, in force_type
    response = BaseResponse(*_run_wsgi_app(response, environ))
  File "/usr/lib/python3/dist-packages/werkzeug/test.py", line 923, in run_wsgi_app
    app_rv = app(environ, start_response)
TypeError: 'dict' object is not callable

During handling of the above exception, another exception occurred:

Traceback (most recent call last):
  File "/usr/lib/python3/dist-packages/flask/app.py", line 2292, in wsgi_app
    response = self.full_dispatch_request()
  File "/usr/lib/python3/dist-packages/flask/app.py", line 1816, in full_dispatch_request
    return self.finalize_request(rv)
  File "/usr/lib/python3/dist-packages/flask/app.py", line 1831, in finalize_request
    response = self.make_response(rv)
  File "/usr/lib/python3/dist-packages/flask/app.py", line 1982, in make_response
    reraise(TypeError, new_error, sys.exc_info()[2])
  File "/usr/lib/python3/dist-packages/flask/_compat.py", line 34, in reraise
    raise value.with_traceback(tb)
  File "/usr/lib/python3/dist-packages/flask/app.py", line 1974, in make_response
    rv = self.response_class.force_type(rv, request.environ)
  File "/usr/lib/python3/dist-packages/werkzeug/wrappers.py", line 921, in force_type
    response = BaseResponse(*_run_wsgi_app(response, environ))
  File "/usr/lib/python3/dist-packages/werkzeug/test.py", line 923, in run_wsgi_app
    app_rv = app(environ, start_response)
TypeError: 'dict' object is not callable
The view function did not return a valid response. The return type must be a string, tuple, Response instance, or WSGI callable, but it was a dict.
192.168.0.187 - - [13/Feb/2021 22:07:01] "GET /tempsens HTTP/1.1" 500 -
Error on request:
Traceback (most recent call last):
  File "/usr/lib/python3/dist-packages/werkzeug/serving.py", line 270, in run_wsgi
    execute(self.server.app)
  File "/usr/lib/python3/dist-packages/werkzeug/serving.py", line 258, in execute
    application_iter = app(environ, start_response)
  File "/usr/lib/python3/dist-packages/flask/app.py", line 2309, in __call__
    return self.wsgi_app(environ, start_response)
  File "/usr/lib/python3/dist-packages/flask/app.py", line 2295, in wsgi_app
    response = self.handle_exception(e)
  File "/usr/lib/python3/dist-packages/flask/app.py", line 1748, in handle_exception
    return self.finalize_request(handler(e), from_error_handler=True)
  File "/usr/lib/python3/dist-packages/flask/app.py", line 1831, in finalize_request
    response = self.make_response(rv)
  File "/usr/lib/python3/dist-packages/flask/app.py", line 1982, in make_response
    reraise(TypeError, new_error, sys.exc_info()[2])
  File "/usr/lib/python3/dist-packages/flask/_compat.py", line 34, in reraise
    raise value.with_traceback(tb)
  File "/usr/lib/python3/dist-packages/flask/app.py", line 1974, in make_response
    rv = self.response_class.force_type(rv, request.environ)
  File "/usr/lib/python3/dist-packages/werkzeug/wrappers.py", line 921, in force_type
    response = BaseResponse(*_run_wsgi_app(response, environ))
  File "/usr/lib/python3/dist-packages/werkzeug/test.py", line 923, in run_wsgi_app
    app_rv = app(environ, start_response)
TypeError: 'dict' object is not callable
The view function did not return a valid response. The return type must be a string, tuple, Response instance, or WSGI callable, but it was a dict.
[2021-02-13 22:07:46,091] ERROR in app: Exception on /tempsens [GET]
Traceback (most recent call last):
  File "/usr/lib/python3/dist-packages/flask/app.py", line 1974, in make_response
    rv = self.response_class.force_type(rv, request.environ)
  File "/usr/lib/python3/dist-packages/werkzeug/wrappers.py", line 921, in force_type
    response = BaseResponse(*_run_wsgi_app(response, environ))
  File "/usr/lib/python3/dist-packages/werkzeug/test.py", line 923, in run_wsgi_app
    app_rv = app(environ, start_response)
TypeError: 'dict' object is not callable

During handling of the above exception, another exception occurred:

Traceback (most recent call last):
  File "/usr/lib/python3/dist-packages/flask/app.py", line 2292, in wsgi_app
    response = self.full_dispatch_request()
  File "/usr/lib/python3/dist-packages/flask/app.py", line 1816, in full_dispatch_request
    return self.finalize_request(rv)
  File "/usr/lib/python3/dist-packages/flask/app.py", line 1831, in finalize_request
    response = self.make_response(rv)
  File "/usr/lib/python3/dist-packages/flask/app.py", line 1982, in make_response
    reraise(TypeError, new_error, sys.exc_info()[2])
  File "/usr/lib/python3/dist-packages/flask/_compat.py", line 34, in reraise
    raise value.with_traceback(tb)
  File "/usr/lib/python3/dist-packages/flask/app.py", line 1974, in make_response
    rv = self.response_class.force_type(rv, request.environ)
  File "/usr/lib/python3/dist-packages/werkzeug/wrappers.py", line 921, in force_type
    response = BaseResponse(*_run_wsgi_app(response, environ))
  File "/usr/lib/python3/dist-packages/werkzeug/test.py", line 923, in run_wsgi_app
    app_rv = app(environ, start_response)
TypeError: 'dict' object is not callable
The view function did not return a valid response. The return type must be a string, tuple, Response instance, or WSGI callable, but it was a dict.
192.168.0.187 - - [13/Feb/2021 22:07:46] "GET /tempsens HTTP/1.1" 500 -
Error on request:
Traceback (most recent call last):
  File "/usr/lib/python3/dist-packages/werkzeug/serving.py", line 270, in run_wsgi
    execute(self.server.app)
  File "/usr/lib/python3/dist-packages/werkzeug/serving.py", line 258, in execute
    application_iter = app(environ, start_response)
  File "/usr/lib/python3/dist-packages/flask/app.py", line 2309, in __call__
    return self.wsgi_app(environ, start_response)
  File "/usr/lib/python3/dist-packages/flask/app.py", line 2295, in wsgi_app
    response = self.handle_exception(e)
  File "/usr/lib/python3/dist-packages/flask/app.py", line 1748, in handle_exception
    return self.finalize_request(handler(e), from_error_handler=True)
  File "/usr/lib/python3/dist-packages/flask/app.py", line 1831, in finalize_request
    response = self.make_response(rv)
  File "/usr/lib/python3/dist-packages/flask/app.py", line 1982, in make_response
    reraise(TypeError, new_error, sys.exc_info()[2])
  File "/usr/lib/python3/dist-packages/flask/_compat.py", line 34, in reraise
    raise value.with_traceback(tb)
  File "/usr/lib/python3/dist-packages/flask/app.py", line 1974, in make_response
    rv = self.response_class.force_type(rv, request.environ)
  File "/usr/lib/python3/dist-packages/werkzeug/wrappers.py", line 921, in force_type
    response = BaseResponse(*_run_wsgi_app(response, environ))
  File "/usr/lib/python3/dist-packages/werkzeug/test.py", line 923, in run_wsgi_app
    app_rv = app(environ, start_response)
TypeError: 'dict' object is not callable
The view function did not return a valid response. The return type must be a string, tuple, Response instance, or WSGI callable, but it was a dict.
[2021-02-13 22:07:46,713] ERROR in app: Exception on /favicon.ico [GET]
Traceback (most recent call last):
  File "/usr/lib/python3/dist-packages/flask/app.py", line 1974, in make_response
    rv = self.response_class.force_type(rv, request.environ)
  File "/usr/lib/python3/dist-packages/werkzeug/wrappers.py", line 921, in force_type
    response = BaseResponse(*_run_wsgi_app(response, environ))
  File "/usr/lib/python3/dist-packages/werkzeug/test.py", line 923, in run_wsgi_app
    app_rv = app(environ, start_response)
TypeError: 'dict' object is not callable

During handling of the above exception, another exception occurred:

Traceback (most recent call last):
  File "/usr/lib/python3/dist-packages/flask/app.py", line 2292, in wsgi_app
    response = self.full_dispatch_request()
  File "/usr/lib/python3/dist-packages/flask/app.py", line 1816, in full_dispatch_request
    return self.finalize_request(rv)
  File "/usr/lib/python3/dist-packages/flask/app.py", line 1831, in finalize_request
    response = self.make_response(rv)
  File "/usr/lib/python3/dist-packages/flask/app.py", line 1982, in make_response
    reraise(TypeError, new_error, sys.exc_info()[2])
  File "/usr/lib/python3/dist-packages/flask/_compat.py", line 34, in reraise
    raise value.with_traceback(tb)
  File "/usr/lib/python3/dist-packages/flask/app.py", line 1974, in make_response
    rv = self.response_class.force_type(rv, request.environ)
  File "/usr/lib/python3/dist-packages/werkzeug/wrappers.py", line 921, in force_type
    response = BaseResponse(*_run_wsgi_app(response, environ))
  File "/usr/lib/python3/dist-packages/werkzeug/test.py", line 923, in run_wsgi_app
    app_rv = app(environ, start_response)
TypeError: 'dict' object is not callable
The view function did not return a valid response. The return type must be a string, tuple, Response instance, or WSGI callable, but it was a dict.
192.168.0.187 - - [13/Feb/2021 22:07:46] "GET /favicon.ico HTTP/1.1" 500 -
Error on request:
Traceback (most recent call last):
  File "/usr/lib/python3/dist-packages/werkzeug/serving.py", line 270, in run_wsgi
    execute(self.server.app)
  File "/usr/lib/python3/dist-packages/werkzeug/serving.py", line 258, in execute
    application_iter = app(environ, start_response)
  File "/usr/lib/python3/dist-packages/flask/app.py", line 2309, in __call__
    return self.wsgi_app(environ, start_response)
  File "/usr/lib/python3/dist-packages/flask/app.py", line 2295, in wsgi_app
    response = self.handle_exception(e)
  File "/usr/lib/python3/dist-packages/flask/app.py", line 1748, in handle_exception
    return self.finalize_request(handler(e), from_error_handler=True)
  File "/usr/lib/python3/dist-packages/flask/app.py", line 1831, in finalize_request
    response = self.make_response(rv)
  File "/usr/lib/python3/dist-packages/flask/app.py", line 1982, in make_response
    reraise(TypeError, new_error, sys.exc_info()[2])
  File "/usr/lib/python3/dist-packages/flask/_compat.py", line 34, in reraise
    raise value.with_traceback(tb)
  File "/usr/lib/python3/dist-packages/flask/app.py", line 1974, in make_response
    rv = self.response_class.force_type(rv, request.environ)
  File "/usr/lib/python3/dist-packages/werkzeug/wrappers.py", line 921, in force_type
    response = BaseResponse(*_run_wsgi_app(response, environ))
  File "/usr/lib/python3/dist-packages/werkzeug/test.py", line 923, in run_wsgi_app
    app_rv = app(environ, start_response)
TypeError: 'dict' object is not callable
The view function did not return a valid response. The return type must be a string, tuple, Response instance, or WSGI callable, but it was a dict.
[2021-02-13 22:07:47,134] ERROR in app: Exception on /favicon.ico [GET]
Traceback (most recent call last):
  File "/usr/lib/python3/dist-packages/flask/app.py", line 1974, in make_response
    rv = self.response_class.force_type(rv, request.environ)
  File "/usr/lib/python3/dist-packages/werkzeug/wrappers.py", line 921, in force_type
    response = BaseResponse(*_run_wsgi_app(response, environ))
  File "/usr/lib/python3/dist-packages/werkzeug/test.py", line 923, in run_wsgi_app
    app_rv = app(environ, start_response)
TypeError: 'dict' object is not callable

During handling of the above exception, another exception occurred:

Traceback (most recent call last):
  File "/usr/lib/python3/dist-packages/flask/app.py", line 2292, in wsgi_app
    response = self.full_dispatch_request()
  File "/usr/lib/python3/dist-packages/flask/app.py", line 1816, in full_dispatch_request
    return self.finalize_request(rv)
  File "/usr/lib/python3/dist-packages/flask/app.py", line 1831, in finalize_request
    response = self.make_response(rv)
  File "/usr/lib/python3/dist-packages/flask/app.py", line 1982, in make_response
    reraise(TypeError, new_error, sys.exc_info()[2])
  File "/usr/lib/python3/dist-packages/flask/_compat.py", line 34, in reraise
    raise value.with_traceback(tb)
  File "/usr/lib/python3/dist-packages/flask/app.py", line 1974, in make_response
    rv = self.response_class.force_type(rv, request.environ)
  File "/usr/lib/python3/dist-packages/werkzeug/wrappers.py", line 921, in force_type
    response = BaseResponse(*_run_wsgi_app(response, environ))
  File "/usr/lib/python3/dist-packages/werkzeug/test.py", line 923, in run_wsgi_app
    app_rv = app(environ, start_response)
TypeError: 'dict' object is not callable
The view function did not return a valid response. The return type must be a string, tuple, Response instance, or WSGI callable, but it was a dict.
192.168.0.187 - - [13/Feb/2021 22:07:47] "GET /favicon.ico HTTP/1.1" 500 -
Error on request:
Traceback (most recent call last):
  File "/usr/lib/python3/dist-packages/werkzeug/serving.py", line 270, in run_wsgi
    execute(self.server.app)
  File "/usr/lib/python3/dist-packages/werkzeug/serving.py", line 258, in execute
    application_iter = app(environ, start_response)
  File "/usr/lib/python3/dist-packages/flask/app.py", line 2309, in __call__
    return self.wsgi_app(environ, start_response)
  File "/usr/lib/python3/dist-packages/flask/app.py", line 2295, in wsgi_app
    response = self.handle_exception(e)
  File "/usr/lib/python3/dist-packages/flask/app.py", line 1748, in handle_exception
    return self.finalize_request(handler(e), from_error_handler=True)
  File "/usr/lib/python3/dist-packages/flask/app.py", line 1831, in finalize_request
    response = self.make_response(rv)
  File "/usr/lib/python3/dist-packages/flask/app.py", line 1982, in make_response
    reraise(TypeError, new_error, sys.exc_info()[2])
  File "/usr/lib/python3/dist-packages/flask/_compat.py", line 34, in reraise
    raise value.with_traceback(tb)
  File "/usr/lib/python3/dist-packages/flask/app.py", line 1974, in make_response
    rv = self.response_class.force_type(rv, request.environ)
  File "/usr/lib/python3/dist-packages/werkzeug/wrappers.py", line 921, in force_type
    response = BaseResponse(*_run_wsgi_app(response, environ))
  File "/usr/lib/python3/dist-packages/werkzeug/test.py", line 923, in run_wsgi_app
    app_rv = app(environ, start_response)
TypeError: 'dict' object is not callable
The view function did not return a valid response. The return type must be a string, tuple, Response instance, or WSGI callable, but it was a dict.
[2021-02-13 22:07:47,586] ERROR in app: Exception on /favicon.ico [GET]
Traceback (most recent call last):
  File "/usr/lib/python3/dist-packages/flask/app.py", line 1974, in make_response
    rv = self.response_class.force_type(rv, request.environ)
  File "/usr/lib/python3/dist-packages/werkzeug/wrappers.py", line 921, in force_type
    response = BaseResponse(*_run_wsgi_app(response, environ))
  File "/usr/lib/python3/dist-packages/werkzeug/test.py", line 923, in run_wsgi_app
    app_rv = app(environ, start_response)
TypeError: 'dict' object is not callable

During handling of the above exception, another exception occurred:

Traceback (most recent call last):
  File "/usr/lib/python3/dist-packages/flask/app.py", line 2292, in wsgi_app
    response = self.full_dispatch_request()
  File "/usr/lib/python3/dist-packages/flask/app.py", line 1816, in full_dispatch_request
    return self.finalize_request(rv)
  File "/usr/lib/python3/dist-packages/flask/app.py", line 1831, in finalize_request
    response = self.make_response(rv)
  File "/usr/lib/python3/dist-packages/flask/app.py", line 1982, in make_response
    reraise(TypeError, new_error, sys.exc_info()[2])
  File "/usr/lib/python3/dist-packages/flask/_compat.py", line 34, in reraise
    raise value.with_traceback(tb)
  File "/usr/lib/python3/dist-packages/flask/app.py", line 1974, in make_response
    rv = self.response_class.force_type(rv, request.environ)
  File "/usr/lib/python3/dist-packages/werkzeug/wrappers.py", line 921, in force_type
    response = BaseResponse(*_run_wsgi_app(response, environ))
  File "/usr/lib/python3/dist-packages/werkzeug/test.py", line 923, in run_wsgi_app
    app_rv = app(environ, start_response)
TypeError: 'dict' object is not callable
The view function did not return a valid response. The return type must be a string, tuple, Response instance, or WSGI callable, but it was a dict.
192.168.0.187 - - [13/Feb/2021 22:07:47] "GET /favicon.ico HTTP/1.1" 500 -
Error on request:
Traceback (most recent call last):
  File "/usr/lib/python3/dist-packages/werkzeug/serving.py", line 270, in run_wsgi
    execute(self.server.app)
  File "/usr/lib/python3/dist-packages/werkzeug/serving.py", line 258, in execute
    application_iter = app(environ, start_response)
  File "/usr/lib/python3/dist-packages/flask/app.py", line 2309, in __call__
    return self.wsgi_app(environ, start_response)
  File "/usr/lib/python3/dist-packages/flask/app.py", line 2295, in wsgi_app
    response = self.handle_exception(e)
  File "/usr/lib/python3/dist-packages/flask/app.py", line 1748, in handle_exception
    return self.finalize_request(handler(e), from_error_handler=True)
  File "/usr/lib/python3/dist-packages/flask/app.py", line 1831, in finalize_request
    response = self.make_response(rv)
  File "/usr/lib/python3/dist-packages/flask/app.py", line 1982, in make_response
    reraise(TypeError, new_error, sys.exc_info()[2])
  File "/usr/lib/python3/dist-packages/flask/_compat.py", line 34, in reraise
    raise value.with_traceback(tb)
  File "/usr/lib/python3/dist-packages/flask/app.py", line 1974, in make_response
    rv = self.response_class.force_type(rv, request.environ)
  File "/usr/lib/python3/dist-packages/werkzeug/wrappers.py", line 921, in force_type
    response = BaseResponse(*_run_wsgi_app(response, environ))
  File "/usr/lib/python3/dist-packages/werkzeug/test.py", line 923, in run_wsgi_app
    app_rv = app(environ, start_response)
TypeError: 'dict' object is not callable
The view function did not return a valid response. The return type must be a string, tuple, Response instance, or WSGI callable, but it was a dict.
192.168.0.187 - - [13/Feb/2021 22:08:48] "GET /tempsens HTTP/1.1" 200 -
192.168.0.187 - - [13/Feb/2021 22:08:53] "GET /tempsens HTTP/1.1" 200 -
192.168.0.187 - - [13/Feb/2021 22:08:54] "GET /static/css/style.css HTTP/1.1" 200 -
192.168.0.187 - - [13/Feb/2021 22:08:54] "GET /static/js/script.js HTTP/1.1" 200 -
192.168.0.187 - - [13/Feb/2021 22:08:56] "POST /tempsens/get_data_json HTTP/1.1" 200 -
192.168.0.187 - - [14/Feb/2021 10:43:25] "GET /tempsens HTTP/1.1" 200 -
192.168.0.187 - - [14/Feb/2021 10:43:25] "GET /static/css/style.css HTTP/1.1" 304 -
192.168.0.187 - - [14/Feb/2021 10:43:25] "GET /static/js/script.js HTTP/1.1" 304 -
192.168.0.187 - - [14/Feb/2021 11:33:56] "GET /tempsens HTTP/1.1" 200 -
192.168.0.187 - - [14/Feb/2021 11:34:00] "GET /tempsens HTTP/1.1" 200 -
192.168.0.187 - - [14/Feb/2021 11:34:04] "POST /tempsens/get_data_json HTTP/1.1" 200 -
192.168.0.169 - - [14/Feb/2021 15:17:35] "GET /tempsens HTTP/1.1" 200 -
192.168.0.169 - - [14/Feb/2021 15:17:41] "POST /tempsens/get_data_json HTTP/1.1" 200 -
192.168.0.169 - - [14/Feb/2021 21:13:41] "GET /tempsens HTTP/1.1" 200 -
192.168.0.169 - - [16/Feb/2021 09:47:02] "GET /tempsens HTTP/1.1" 200 -
192.168.0.169 - - [16/Feb/2021 09:47:02] "GET /static/css/style.css HTTP/1.1" 304 -
192.168.0.169 - - [16/Feb/2021 09:47:02] "GET /static/js/script.js HTTP/1.1" 304 -
192.168.0.169 - - [16/Feb/2021 11:15:53] "GET /static/favicon.ico HTTP/1.1" 200 -
192.168.0.169 - - [16/Feb/2021 11:15:58] "GET /tempsens HTTP/1.1" 200 -
